Workbook

Sheet Raw
A1: namespaces: | F1: "
B2: https://onerecord.iata.org/ns/cargo#
B3: https://onerecord.iata.org/ns/code-lists/
B4: http://www.w3.org/2001/XMLSchema# | F4: _ instead of : because of filenames :(
AP5: Core | AV5: Full
A6: SPARQL results: | L6: Normalized IRIs: | Q6: Property Type: | R6: syntax tables: | AF6: csv tables concat: | AG6: csv edges
A7: type | B7: element | C7: class | D7: property | E7: elementValue | F7: value | G7: cardinality | H7: inverse | I7: class_description_full | J7: property_description_full | K7: value_subclasses | L7: class | M7: property | N7: value | O7: inverse | P7: value_subclasses | Q7: type | R7: "table_schema" | S7: "table_name" | T7: "column_name" | U7: "schema_type" | V7: "data_type" | W7: "ordinal_position" | X7: "table_description" | Y7: "property_description" | Z7: "is_array" | AA7: "is_codelist" | AB7: "data_type_subclasses" | AC7: "class_IRI" | AD7: "property_IRI" | AE7: "value_IRI" | AF7: =IF(A7="Implicit","",R7&","&S7&","&T7&","&U7&","&V7&","&W7&","&X7&","&Y7&","&Z7&","&AA7&","&AB7&","&AC7&","&AD7&","&AE7) -> "table_schema","table_name","column_name","schema_type","data_type","ordinal_position","table_description","property_description","is_array","is_codelist","data_type_subclasses","class_IRI","property_IRI","value_IRI" | AG7: "source" | AH7: "sourceKey" | AI7: "target" | AJ7: "targetKey" | AK7: "relation" | AL7: "source","sourceKey","target","targetKey","relation" | AN7: Class | AO7: Link | AQ7: =AF7 -> "table_schema","table_name","column_name","schema_type","data_type","ordinal_position","table_description","property_description","is_array","is_codelist","data_type_subclasses","class_IRI","property_IRI","value_IRI" | AR7: =AL7 -> "source","sourceKey","target","targetKey","relation" | AT7: Class | AU7: Link | AV7: Link_Manual | AW7: =AF7 -> "table_schema","table_name","column_name","schema_type","data_type","ordinal_position","table_description","property_description","is_array","is_codelist","data_type_subclasses","class_IRI","property_IRI","value_IRI" | AX7: =AR7 -> "source","sourceKey","target","targetKey","relation" | AY7: =AX7 -> "source","sourceKey","target","targetKey","relation"
A8: Explicit | B8: Embedded | C8: https://onerecord.iata.org/ns/cargo#AccountNumber | D8: https://onerecord.iata.org/ns/cargo#accountNumberType | E8: Enum | F8: https://onerecord.iata.org/ns/cargo#AccountType | G8: 1 | J8: Type of the account of the account number | L8: =SUBSTITUTE(SUBSTITUTE(SUBSTITUTE(C8,$B$2,$A$2),$B$3,$A$3),$B$4,$A$4) -> AccountNumber | M8: =SUBSTITUTE(SUBSTITUTE(SUBSTITUTE(D8,$B$2,$A$2),$B$3,$A$3),$A$4,$B$4) -> accountNumberType | N8: =SUBSTITUTE(SUBSTITUTE(SUBSTITUTE(F8,$B$2,$A$2),$B$3,$A$3),$B$4,$A$4) -> AccountType | O8: =SUBSTITUTE(SUBSTITUTE(SUBSTITUTE(H8,$B$2,$A$2),$B$3,$A$3),$B$4,$A$4) | P8: =SUBSTITUTE(SUBSTITUTE(SUBSTITUTE(K8,$B$2,$A$2),$B$3,$A$3),$B$4,$A$4) | Q8: =IF(LEFT(N8,3)="xsd","Data","Object") -> Object | R8: =IF($A8="Implicit","",$F$1&B8&$F$1) -> "Embedded" | S8: =IF($A8="Implicit","",$F$1&L8&$F$1) -> "AccountNumber" | T8: =IF($A8="Implicit","",$F$1&M8&$F$1) -> "accountNumberType" | U8: =IF($A8="Implicit","",$F$1&E8&$F$1) -> "Enum" | V8: =IF($A8="Implicit","",$F$1&N8&$F$1) -> "AccountType" | W8: =IF($A8="Implicit","",COUNTIFS($C$8:C8,C8,$A$8:A8,"Explicit")) -> 1 | X8: =IF($A8="Implicit","",$F$1&SUBSTITUTE(IF(I8=0,"",I8),",",";")&$F$1) -> "" | Y8: =IF($A8="Implicit","",$F$1&SUBSTITUTE(IF(J8=0,"",J8),",",";")&$F$1) -> "Type of the account of the account number" | Z8: =IF($A8="Implicit","",$F$1&IF(G8=1,"false","true")&$F$1) -> "false" | AA8: =IF($A8="Implicit","",$F$1&IF(OR(E8="Enum",E8="CodeList"),"true","false")&$F$1) -> "true" | AB8: =IF($A8="Implicit","",$F$1&P8&$F$1) -> "" | AC8: =IF($A8="Implicit","",$F$1&C8&$F$1) -> "https://onerecord.iata.org/ns/cargo#AccountNumber" | AD8: =IF($A8="Implicit","",$F$1&D8&$F$1) -> "https://onerecord.iata.org/ns/cargo#accountNumberType" | AE8: =IF($A8="Implicit","",$F$1&F8&$F$1) -> "https://onerecord.iata.org/ns/cargo#AccountType" | AF8: =IF(A8="Implicit","",R8&","&S8&","&T8&","&U8&","&V8&","&W8&","&X8&","&Y8&","&Z8&","&AA8&","&AB8&","&AC8&","&AD8&","&AE8) -> "Embedded","AccountNumber","accountNumberType","Enum","AccountType",1,"","Type of the account of the account number","false","true","","https://onerecord.iata.org/ns/cargo#AccountNumber","https://onerecord.iata.org/ns/cargo#accountNumberType","https://onerecord.iata.org/ns/cargo#AccountType" | AG8: =IF(Q8="Data","",$F$1&B8&"."&L8&$F$1) -> "Embedded.AccountNumber" | AH8: =IF(Q8="Data","",$F$1&M8&$F$1) -> "accountNumberType" | AI8: =IF(Q8="Data","",$F$1&E8&"."&N8&$F$1) -> "Enum.AccountType" | AJ8: =IF(Q8="Data","",$F$1&O8&$F$1) -> "" | AK8: =IF(Q8="Data","",$F$1&IF(G8=1,"hasOne","hasMany")&$F$1) -> "hasOne" | AL8: =IF(Q8="Data","",AG8&","&AH8&","&AI8&","&AJ8&","&AK8) -> "Embedded.AccountNumber","accountNumberType","Enum.AccountType","","hasOne" | AN8: =COUNTIF(View_conceptual!G:G,L8) -> 0 | AO8: =COUNTIF(View_conceptual!H:H,L8)+COUNTIF(View_conceptual!I:I,N8) -> 0 | AQ8: =IF(AN8=1,AF8,"") | AR8: =IF(AO8=2,AL8,"") | AT8: =COUNTIF(View_full!G:G,L8) -> 0 | AU8: =COUNTIF(View_full!H:H,L8)+COUNTIF(View_full!I:I,N8) -> 0 | AV8: =COUNTIFS(Property_Manual!$A$2:$A$1206,Raw!L8,Property_Manual!$B$2:$B$1206,Raw!M8,Property_Manual!$C$2:$C$1206,Raw!N8,Property_Manual!$D$2:$D$1206,Raw!O8,Property_Manual!$F$2:$F$1206,"x") -> 0 | AW8: =IF(AT8=1,AF8,"") | AX8: =IF(AU8=2,AL8,"") | AY8: =IF(AV8=1,AL8,"")
A9: Implicit | B9: Embedded | C9: https://onerecord.iata.org/ns/cargo#AccountNumber | D9: https://onerecord.iata.org/ns/cargo#accountNumberType | E9: Enum | F9: https://onerecord.iata.org/ns/cargo#AccountType | G9: 1 | J9: Type of the account of the account number | L9: =SUBSTITUTE(SUBSTITUTE(SUBSTITUTE(C9,$B$2,$A$2),$B$3,$A$3),$B$4,$A$4) -> AccountNumber | M9: =SUBSTITUTE(SUBSTITUTE(SUBSTITUTE(D9,$B$2,$A$2),$B$3,$A$3),$A$4,$B$4) -> accountNumberType | N9: =SUBSTITUTE(SUBSTITUTE(SUBSTITUTE(F9,$B$2,$A$2),$B$3,$A$3),$B$4,$A$4) -> AccountType | O9: =SUBSTITUTE(SUBSTITUTE(SUBSTITUTE(H9,$B$2,$A$2),$B$3,$A$3),$B$4,$A$4) | P9: =SUBSTITUTE(SUBSTITUTE(SUBSTITUTE(K9,$B$2,$A$2),$B$3,$A$3),$B$4,$A$4) | Q9: =IF(LEFT(N9,3)="xsd","Data","Object") -> Object | R9: =IF($A9="Implicit","",$F$1&B9&$F$1) | S9: =IF($A9="Implicit","",$F$1&L9&$F$1) | T9: =IF($A9="Implicit","",$F$1&M9&$F$1) | U9: =IF($A9="Implicit","",$F$1&E9&$F$1) | V9: =IF($A9="Implicit","",$F$1&N9&$F$1) | W9: =IF($A9="Implicit","",COUNTIFS($C$8:C9,C9,$A$8:A9,"Explicit")) | X9: =IF($A9="Implicit","",$F$1&SUBSTITUTE(IF(I9=0,"",I9),",",";")&$F$1) | Y9: =IF($A9="Implicit","",$F$1&SUBSTITUTE(IF(J9=0,"",J9),",",";")&$F$1) | Z9: =IF($A9="Implicit","",$F$1&IF(G9=1,"false","true")&$F$1) | AA9: =IF($A9="Implicit","",$F$1&IF(OR(E9="Enum",E9="CodeList"),"true","false")&$F$1) | AB9: =IF($A9="Implicit","",$F$1&P9&$F$1) | AC9: =IF($A9="Implicit","",$F$1&C9&$F$1) | AD9: =IF($A9="Implicit","",$F$1&D9&$F$1) | AE9: =IF($A9="Implicit","",$F$1&F9&$F$1) | AF9: =IF(A9="Implicit","",R9&","&S9&","&T9&","&U9&","&V9&","&W9&","&X9&","&Y9&","&Z9&","&AA9&","&AB9&","&AC9&","&AD9&","&AE9) | AG9: =IF(Q9="Data","",$F$1&B9&"."&L9&$F$1) -> "Embedded.AccountNumber" | AH9: =IF(Q9="Data","",$F$1&M9&$F$1) -> "accountNumberType" | AI9: =IF(Q9="Data","",$F$1&E9&"."&N9&$F$1) -> "Enum.AccountType" | AJ9: =IF(Q9="Data","",$F$1&O9&$F$1) -> "" | AK9: =IF(Q9="Data","",$F$1&IF(G9=1,"hasOne","hasMany")&$F$1) -> "hasOne" | AL9: =IF(Q9="Data","",AG9&","&AH9&","&AI9&","&AJ9&","&AK9) -> "Embedded.AccountNumber","accountNumberType","Enum.AccountType","","hasOne" | AN9: =COUNTIF(View_conceptual!G:G,L9) -> 0 | AO9: =COUNTIF(View_conceptual!H:H,L9)+COUNTIF(View_conceptual!I:I,N9) -> 0 | AQ9: =IF(AN9=1,AF9,"") | AR9: =IF(AO9=2,AL9,"") | AT9: =COUNTIF(View_full!G:G,L9) -> 0 | AU9: =COUNTIF(View_full!H:H,L9)+COUNTIF(View_full!I:I,N9) -> 0 | AV9: =COUNTIFS(Property_Manual!$A$2:$A$1206,Raw!L9,Property_Manual!$B$2:$B$1206,Raw!M9,Property_Manual!$C$2:$C$1206,Raw!N9,Property_Manual!$D$2:$D$1206,Raw!O9,Property_Manual!$F$2:$F$1206,"x") -> 0 | AW9: =IF(AT9=1,AF9,"") | AX9: =IF(AU9=2,AL9,"") | AY9: =IF(AV9=1,AL9,"")
A10: Explicit | B10: Embedded | C10: https://onerecord.iata.org/ns/cargo#AccountNumber | D10: https://onerecord.iata.org/ns/cargo#textualValue | F10: http://www.w3.org/2001/XMLSchema#string | G10: 1 | J10: Textual value filled on use context (eg. characteristic colour, contactDetail mail address, etc.) | L10: =SUBSTITUTE(SUBSTITUTE(SUBSTITUTE(C10,$B$2,$A$2),$B$3,$A$3),$B$4,$A$4) -> AccountNumber | M10: =SUBSTITUTE(SUBSTITUTE(SUBSTITUTE(D10,$B$2,$A$2),$B$3,$A$3),$A$4,$B$4) -> textualValue | N10: =SUBSTITUTE(SUBSTITUTE(SUBSTITUTE(F10,$B$2,$A$2),$B$3,$A$3),$B$4,$A$4) -> string | O10: =SUBSTITUTE(SUBSTITUTE(SUBSTITUTE(H10,$B$2,$A$2),$B$3,$A$3),$B$4,$A$4) | P10: =SUBSTITUTE(SUBSTITUTE(SUBSTITUTE(K10,$B$2,$A$2),$B$3,$A$3),$B$4,$A$4) | Q10: =IF(LEFT(N10,3)="xsd","Data","Object") -> Object | R10: =IF($A10="Implicit","",$F$1&B10&$F$1) -> "Embedded" | S10: =IF($A10="Implicit","",$F$1&L10&$F$1) -> "AccountNumber" | T10: =IF($A10="Implicit","",$F$1&M10&$F$1) -> "textualValue" | U10: =IF($A10="Implicit","",$F$1&E10&$F$1) -> "" | V10: =IF($A10="Implicit","",$F$1&N10&$F$1) -> "string" | W10: =IF($A10="Implicit","",COUNTIFS($C$8:C10,C10,$A$8:A10,"Explicit")) -> 2 | X10: =IF($A10="Implicit","",$F$1&SUBSTITUTE(IF(I10=0,"",I10),",",";")&$F$1) -> "" | Y10: =IF($A10="Implicit","",$F$1&SUBSTITUTE(IF(J10=0,"",J10),",",";")&$F$1) -> "Textual value filled on use context (eg. characteristic colour; contactDetail mail address; etc.)" | Z10: =IF($A10="Implicit","",$F$1&IF(G10=1,"false","true")&$F$1) -> "false" | AA10: =IF($A10="Implicit","",$F$1&IF(OR(E10="Enum",E10="CodeList"),"true","false")&$F$1) -> "false" | AB10: =IF($A10="Implicit","",$F$1&P10&$F$1) -> "" | AC10: =IF($A10="Implicit","",$F$1&C10&$F$1) -> "https://onerecord.iata.org/ns/cargo#AccountNumber" | AD10: =IF($A10="Implicit","",$F$1&D10&$F$1) -> "https://onerecord.iata.org/ns/cargo#textualValue" | AE10: =IF($A10="Implicit","",$F$1&F10&$F$1) -> "http://www.w3.org/2001/XMLSchema#string" | AF10: =IF(A10="Implicit","",R10&","&S10&","&T10&","&U10&","&V10&","&W10&","&X10&","&Y10&","&Z10&","&AA10&","&AB10&","&AC10&","&AD10&","&AE10) -> "Embedded","AccountNumber","textualValue","","string",2,"","Textual value filled on use context (eg. characteristic colour; contactDetail mail address; etc.)","false","false","","https://onerecord.iata.org/ns/cargo#AccountNumber","https://onerecord.iata.org/ns/cargo#textualValue","http://www.w3.org/2001/XMLSchema#string" | AG10: =IF(Q10="Data","",$F$1&B10&"."&L10&$F$1) -> "Embedded.AccountNumber" | AH10: =IF(Q10="Data","",$F$1&M10&$F$1) -> "textualValue" | AI10: =IF(Q10="Data","",$F$1&E10&"."&N10&$F$1) -> ".string" | AJ10: =IF(Q10="Data","",$F$1&O10&$F$1) -> "" | AK10: =IF(Q10="Data","",$F$1&IF(G10=1,"hasOne","hasMany")&$F$1) -> "hasOne" | AL10: =IF(Q10="Data","",AG10&","&AH10&","&AI10&","&AJ10&","&AK10) -> "Embedded.AccountNumber","textualValue",".string","","hasOne" | AN10: =COUNTIF(View_conceptual!G:G,L10) -> 0 | AO10: =COUNTIF(View_conceptual!H:H,L10)+COUNTIF(View_conceptual!I:I,N10) -> 0 | AQ10: =IF(AN10=1,AF10,"") | AR10: =IF(AO10=2,AL10,"") | AT10: =COUNTIF(View_full!G:G,L10) -> 0 | AU10: =COUNTIF(View_full!H:H,L10)+COUNTIF(View_full!I:I,N10) -> 0 | AV10: =COUNTIFS(Property_Manual!$A$2:$A$1206,Raw!L10,Property_Manual!$B$2:$B$1206,Raw!M10,Property_Manual!$C$2:$C$1206,Raw!N10,Property_Manual!$D$2:$D$1206,Raw!O10,Property_Manual!$F$2:$F$1206,"x") -> 0 | AW10: =IF(AT10=1,AF10,"") | AX10: =IF(AU10=2,AL10,"") | AY10: =IF(AV10=1,AL10,"")
A11: Explicit | B11: Enum | C11: https://onerecord.iata.org/ns/cargo#AccountType | D11: https://onerecord.iata.org/ns/cargo#code | F11: http://www.w3.org/2001/XMLSchema#string | G11: 1 | I11: Open code list for Account types | J11: Code or short version of a code, for example "CH" for Switzerland when referring to the UN/LOCODE code list | L11: =SUBSTITUTE(SUBSTITUTE(SUBSTITUTE(C11,$B$2,$A$2),$B$3,$A$3),$B$4,$A$4) -> AccountType | M11: =SUBSTITUTE(SUBSTITUTE(SUBSTITUTE(D11,$B$2,$A$2),$B$3,$A$3),$A$4,$B$4) -> code | N11: =SUBSTITUTE(SUBSTITUTE(SUBSTITUTE(F11,$B$2,$A$2),$B$3,$A$3),$B$4,$A$4) -> string | O11: =SUBSTITUTE(SUBSTITUTE(SUBSTITUTE(H11,$B$2,$A$2),$B$3,$A$3),$B$4,$A$4) | P11: =SUBSTITUTE(SUBSTITUTE(SUBSTITUTE(K11,$B$2,$A$2),$B$3,$A$3),$B$4,$A$4) | Q11: =IF(LEFT(N11,3)="xsd","Data","Object") -> Object | R11: =IF($A11="Implicit","",$F$1&B11&$F$1) -> "Enum" | S11: =IF($A11="Implicit","",$F$1&L11&$F$1) -> "AccountType" | T11: =IF($A11="Implicit","",$F$1&M11&$F$1) -> "code" | U11: =IF($A11="Implicit","",$F$1&E11&$F$1) -> "" | V11: =IF($A11="Implicit","",$F$1&N11&$F$1) -> "string" | W11: =IF($A11="Implicit","",COUNTIFS($C$8:C11,C11,$A$8:A11,"Explicit")) -> 1 | X11: =IF($A11="Implicit","",$F$1&SUBSTITUTE(IF(I11=0,"",I11),",",";")&$F$1) -> "Open code list for Account types" | Y11: =IF($A11="Implicit","",$F$1&SUBSTITUTE(IF(J11=0,"",J11),",",";")&$F$1) -> "Code or short version of a code; for example "CH" for Switzerland when referring to the UN/LOCODE code list" | Z11: =IF($A11="Implicit","",$F$1&IF(G11=1,"false","true")&$F$1) -> "false" | AA11: =IF($A11="Implicit","",$F$1&IF(OR(E11="Enum",E11="CodeList"),"true","false")&$F$1) -> "false" | AB11: =IF($A11="Implicit","",$F$1&P11&$F$1) -> "" | AC11: =IF($A11="Implicit","",$F$1&C11&$F$1) -> "https://onerecord.iata.org/ns/cargo#AccountType" | AD11: =IF($A11="Implicit","",$F$1&D11&$F$1) -> "https://onerecord.iata.org/ns/cargo#code" | AE11: =IF($A11="Implicit","",$F$1&F11&$F$1) -> "http://www.w3.org/2001/XMLSchema#string" | AF11: =IF(A11="Implicit","",R11&","&S11&","&T11&","&U11&","&V11&","&W11&","&X11&","&Y11&","&Z11&","&AA11&","&AB11&","&AC11&","&AD11&","&AE11) -> "Enum","AccountType","code","","string",1,"Open code list for Account types","Code or short version of a code; for example "CH" for Switzerland when referring to the UN/LOCODE code list","false","false","","https://onerecord.iata.org/ns/cargo#AccountType","https://onerecord.iata.org/ns/cargo#code","http://www.w3.org/2001/XMLSchema#string" | AG11: =IF(Q11="Data","",$F$1&B11&"."&L11&$F$1) -> "Enum.AccountType" | AH11: =IF(Q11="Data","",$F$1&M11&$F$1) -> "code" | AI11: =IF(Q11="Data","",$F$1&E11&"."&N11&$F$1) -> ".string" | AJ11: =IF(Q11="Data","",$F$1&O11&$F$1) -> "" | AK11: =IF(Q11="Data","",$F$1&IF(G11=1,"hasOne","hasMany")&$F$1) -> "hasOne" | AL11: =IF(Q11="Data","",AG11&","&AH11&","&AI11&","&AJ11&","&AK11) -> "Enum.AccountType","code",".string","","hasOne" | AN11: =COUNTIF(View_conceptual!G:G,L11) -> 0 | AO11: =COUNTIF(View_conceptual!H:H,L11)+COUNTIF(View_conceptual!I:I,N11) -> 0 | AQ11: =IF(AN11=1,AF11,"") | AR11: =IF(AO11=2,AL11,"") | AT11: =COUNTIF(View_full!G:G,L11) -> 0 | AU11: =COUNTIF(View_full!H:H,L11)+COUNTIF(View_full!I:I,N11) -> 0 | AV11: =COUNTIFS(Property_Manual!$A$2:$A$1206,Raw!L11,Property_Manual!$B$2:$B$1206,Raw!M11,Property_Manual!$C$2:$C$1206,Raw!N11,Property_Manual!$D$2:$D$1206,Raw!O11,Property_Manual!$F$2:$F$1206,"x") -> 0 | AW11: =IF(AT11=1,AF11,"") | AX11: =IF(AU11=2,AL11,"") | AY11: =IF(AV11=1,AL11,"")
A12: Explicit | B12: Enum | C12: https://onerecord.iata.org/ns/cargo#AccountType | D12: https://onerecord.iata.org/ns/cargo#codeDescription | F12: http://www.w3.org/2001/XMLSchema#string | G12: 1 | I12: Open code list for Account types | J12: Description or long version of the code, for example "Switzerland" for Switzerland when referring to the UN/LOCODE code list | L12: =SUBSTITUTE(SUBSTITUTE(SUBSTITUTE(C12,$B$2,$A$2),$B$3,$A$3),$B$4,$A$4) -> AccountType | M12: =SUBSTITUTE(SUBSTITUTE(SUBSTITUTE(D12,$B$2,$A$2),$B$3,$A$3),$A$4,$B$4) -> codeDescription | N12: =SUBSTITUTE(SUBSTITUTE(SUBSTITUTE(F12,$B$2,$A$2),$B$3,$A$3),$B$4,$A$4) -> string | O12: =SUBSTITUTE(SUBSTITUTE(SUBSTITUTE(H12,$B$2,$A$2),$B$3,$A$3),$B$4,$A$4) | P12: =SUBSTITUTE(SUBSTITUTE(SUBSTITUTE(K12,$B$2,$A$2),$B$3,$A$3),$B$4,$A$4) | Q12: =IF(LEFT(N12,3)="xsd","Data","Object") -> Object | R12: =IF($A12="Implicit","",$F$1&B12&$F$1) -> "Enum" | S12: =IF($A12="Implicit","",$F$1&L12&$F$1) -> "AccountType" | T12: =IF($A12="Implicit","",$F$1&M12&$F$1) -> "codeDescription" | U12: =IF($A12="Implicit","",$F$1&E12&$F$1) -> "" | V12: =IF($A12="Implicit","",$F$1&N12&$F$1) -> "string" | W12: =IF($A12="Implicit","",COUNTIFS($C$8:C12,C12,$A$8:A12,"Explicit")) -> 2 | X12: =IF($A12="Implicit","",$F$1&SUBSTITUTE(IF(I12=0,"",I12),",",";")&$F$1) -> "Open code list for Account types" | Y12: =IF($A12="Implicit","",$F$1&SUBSTITUTE(IF(J12=0,"",J12),",",";")&$F$1) -> "Description or long version of the code; for example "Switzerland" for Switzerland when referring to the UN/LOCODE code list" | Z12: =IF($A12="Implicit","",$F$1&IF(G12=1,"false","true")&$F$1) -> "false" | AA12: =IF($A12="Implicit","",$F$1&IF(OR(E12="Enum",E12="CodeList"),"true","false")&$F$1) -> "false" | AB12: =IF($A12="Implicit","",$F$1&P12&$F$1) -> "" | AC12: =IF($A12="Implicit","",$F$1&C12&$F$1) -> "https://onerecord.iata.org/ns/cargo#AccountType" | AD12: =IF($A12="Implicit","",$F$1&D12&$F$1) -> "https://onerecord.iata.org/ns/cargo#codeDescription" | AE12: =IF($A12="Implicit","",$F$1&F12&$F$1) -> "http://www.w3.org/2001/XMLSchema#string" | AF12: =IF(A12="Implicit","",R12&","&S12&","&T12&","&U12&","&V12&","&W12&","&X12&","&Y12&","&Z12&","&AA12&","&AB12&","&AC12&","&AD12&","&AE12) -> "Enum","AccountType","codeDescription","","string",2,"Open code list for Account types","Description or long version of the code; for example "Switzerland" for Switzerland when referring to the UN/LOCODE code list","false","false","","https://onerecord.iata.org/ns/cargo#AccountType","https://onerecord.iata.org/ns/cargo#codeDescription","http://www.w3.org/2001/XMLSchema#string" | AG12: =IF(Q12="Data","",$F$1&B12&"."&L12&$F$1) -> "Enum.AccountType" | AH12: =IF(Q12="Data","",$F$1&M12&$F$1) -> "codeDescription" | AI12: =IF(Q12="Data","",$F$1&E12&"."&N12&$F$1) -> ".string" | AJ12: =IF(Q12="Data","",$F$1&O12&$F$1) -> "" | AK12: =IF(Q12="Data","",$F$1&IF(G12=1,"hasOne","hasMany")&$F$1) -> "hasOne" | AL12: =IF(Q12="Data","",AG12&","&AH12&","&AI12&","&AJ12&","&AK12) -> "Enum.AccountType","codeDescription",".string","","hasOne" | AN12: =COUNTIF(View_conceptual!G:G,L12) -> 0 | AO12: =COUNTIF(View_conceptual!H:H,L12)+COUNTIF(View_conceptual!I:I,N12) -> 0 | AQ12: =IF(AN12=1,AF12,"") | AR12: =IF(AO12=2,AL12,"") | AT12: =COUNTIF(View_full!G:G,L12) -> 0 | AU12: =COUNTIF(View_full!H:H,L12)+COUNTIF(View_full!I:I,N12) -> 0 | AV12: =COUNTIFS(Property_Manual!$A$2:$A$1206,Raw!L12,Property_Manual!$B$2:$B$1206,Raw!M12,Property_Manual!$C$2:$C$1206,Raw!N12,Property_Manual!$D$2:$D$1206,Raw!O12,Property_Manual!$F$2:$F$1206,"x") -> 0 | AW12: =IF(AT12=1,AF12,"") | AX12: =IF(AU12=2,AL12,"") | AY12: =IF(AV12=1,AL12,"")
A13: Explicit | B13: Enum | C13: https://onerecord.iata.org/ns/cargo#AccountType | D13: https://onerecord.iata.org/ns/cargo#codeLevel | F13: http://www.w3.org/2001/XMLSchema#integer | G13: 1 | I13: Open code list for Account types | J13: Integer indicating the level of a code if a codelists is hierarchical, for example HS-Codes | L13: =SUBSTITUTE(SUBSTITUTE(SUBSTITUTE(C13,$B$2,$A$2),$B$3,$A$3),$B$4,$A$4) -> AccountType | M13: =SUBSTITUTE(SUBSTITUTE(SUBSTITUTE(D13,$B$2,$A$2),$B$3,$A$3),$A$4,$B$4) -> codeLevel | N13: =SUBSTITUTE(SUBSTITUTE(SUBSTITUTE(F13,$B$2,$A$2),$B$3,$A$3),$B$4,$A$4) -> integer | O13: =SUBSTITUTE(SUBSTITUTE(SUBSTITUTE(H13,$B$2,$A$2),$B$3,$A$3),$B$4,$A$4) | P13: =SUBSTITUTE(SUBSTITUTE(SUBSTITUTE(K13,$B$2,$A$2),$B$3,$A$3),$B$4,$A$4) | Q13: =IF(LEFT(N13,3)="xsd","Data","Object") -> Object | R13: =IF($A13="Implicit","",$F$1&B13&$F$1) -> "Enum" | S13: =IF($A13="Implicit","",$F$1&L13&$F$1) -> "AccountType" | T13: =IF($A13="Implicit","",$F$1&M13&$F$1) -> "codeLevel" | U13: =IF($A13="Implicit","",$F$1&E13&$F$1) -> "" | V13: =IF($A13="Implicit","",$F$1&N13&$F$1) -> "integer" | W13: =IF($A13="Implicit","",COUNTIFS($C$8:C13,C13,$A$8:A13,"Explicit")) -> 3 | X13: =IF($A13="Implicit","",$F$1&SUBSTITUTE(IF(I13=0,"",I13),",",";")&$F$1) -> "Open code list for Account types" | Y13: =IF($A13="Implicit","",$F$1&SUBSTITUTE(IF(J13=0,"",J13),",",";")&$F$1) -> "Integer indicating the level of a code if a codelists is hierarchical; for example HS-Codes" | Z13: =IF($A13="Implicit","",$F$1&IF(G13=1,"false","true")&$F$1) -> "false" | AA13: =IF($A13="Implicit","",$F$1&IF(OR(E13="Enum",E13="CodeList"),"true","false")&$F$1) -> "false" | AB13: =IF($A13="Implicit","",$F$1&P13&$F$1) -> "" | AC13: =IF($A13="Implicit","",$F$1&C13&$F$1) -> "https://onerecord.iata.org/ns/cargo#AccountType" | AD13: =IF($A13="Implicit","",$F$1&D13&$F$1) -> "https://onerecord.iata.org/ns/cargo#codeLevel" | AE13: =IF($A13="Implicit","",$F$1&F13&$F$1) -> "http://www.w3.org/2001/XMLSchema#integer" | AF13: =IF(A13="Implicit","",R13&","&S13&","&T13&","&U13&","&V13&","&W13&","&X13&","&Y13&","&Z13&","&AA13&","&AB13&","&AC13&","&AD13&","&AE13) -> "Enum","AccountType","codeLevel","","integer",3,"Open code list for Account types","Integer indicating the level of a code if a codelists is hierarchical; for example HS-Codes","false","false","","https://onerecord.iata.org/ns/cargo#AccountType","https://onerecord.iata.org/ns/cargo#codeLevel","http://www.w3.org/2001/XMLSchema#integer" | AG13: =IF(Q13="Data","",$F$1&B13&"."&L13&$F$1) -> "Enum.AccountType" | AH13: =IF(Q13="Data","",$F$1&M13&$F$1) -> "codeLevel" | AI13: =IF(Q13="Data","",$F$1&E13&"."&N13&$F$1) -> ".integer" | AJ13: =IF(Q13="Data","",$F$1&O13&$F$1) -> "" | AK13: =IF(Q13="Data","",$F$1&IF(G13=1,"hasOne","hasMany")&$F$1) -> "hasOne" | AL13: =IF(Q13="Data","",AG13&","&AH13&","&AI13&","&AJ13&","&AK13) -> "Enum.AccountType","codeLevel",".integer","","hasOne" | AN13: =COUNTIF(View_conceptual!G:G,L13) -> 0 | AO13: =COUNTIF(View_conceptual!H:H,L13)+COUNTIF(View_conceptual!I:I,N13) -> 0 | AQ13: =IF(AN13=1,AF13,"") | AR13: =IF(AO13=2,AL13,"") | AT13: =COUNTIF(View_full!G:G,L13) -> 0 | AU13: =COUNTIF(View_full!H:H,L13)+COUNTIF(View_full!I:I,N13) -> 0 | AV13: =COUNTIFS(Property_Manual!$A$2:$A$1206,Raw!L13,Property_Manual!$B$2:$B$1206,Raw!M13,Property_Manual!$C$2:$C$1206,Raw!N13,Property_Manual!$D$2:$D$1206,Raw!O13,Property_Manual!$F$2:$F$1206,"x") -> 0 | AW13: =IF(AT13=1,AF13,"") | AX13: =IF(AU13=2,AL13,"") | AY13: =IF(AV13=1,AL13,"")
A14: Explicit | B14: Enum | C14: https://onerecord.iata.org/ns/cargo#AccountType | D14: https://onerecord.iata.org/ns/cargo#codeListName | F14: http://www.w3.org/2001/XMLSchema#string | G14: 1 | I14: Open code list for Account types | J14: Official name of the code list without version number when direct reference is not possible, for example "UN/LOCODE" when referring to the UN/LOCODE code list | L14: =SUBSTITUTE(SUBSTITUTE(SUBSTITUTE(C14,$B$2,$A$2),$B$3,$A$3),$B$4,$A$4) -> AccountType | M14: =SUBSTITUTE(SUBSTITUTE(SUBSTITUTE(D14,$B$2,$A$2),$B$3,$A$3),$A$4,$B$4) -> codeListName | N14: =SUBSTITUTE(SUBSTITUTE(SUBSTITUTE(F14,$B$2,$A$2),$B$3,$A$3),$B$4,$A$4) -> string | O14: =SUBSTITUTE(SUBSTITUTE(SUBSTITUTE(H14,$B$2,$A$2),$B$3,$A$3),$B$4,$A$4) | P14: =SUBSTITUTE(SUBSTITUTE(SUBSTITUTE(K14,$B$2,$A$2),$B$3,$A$3),$B$4,$A$4) | Q14: =IF(LEFT(N14,3)="xsd","Data","Object") -> Object | R14: =IF($A14="Implicit","",$F$1&B14&$F$1) -> "Enum" | S14: =IF($A14="Implicit","",$F$1&L14&$F$1) -> "AccountType" | T14: =IF($A14="Implicit","",$F$1&M14&$F$1) -> "codeListName" | U14: =IF($A14="Implicit","",$F$1&E14&$F$1) -> "" | V14: =IF($A14="Implicit","",$F$1&N14&$F$1) -> "string" | W14: =IF($A14="Implicit","",COUNTIFS($C$8:C14,C14,$A$8:A14,"Explicit")) -> 4 | X14: =IF($A14="Implicit","",$F$1&SUBSTITUTE(IF(I14=0,"",I14),",",";")&$F$1) -> "Open code list for Account types" | Y14: =IF($A14="Implicit","",$F$1&SUBSTITUTE(IF(J14=0,"",J14),",",";")&$F$1) -> "Official name of the code list without version number when direct reference is not possible; for example "UN/LOCODE" when referring to the UN/LOCODE code list" | Z14: =IF($A14="Implicit","",$F$1&IF(G14=1,"false","true")&$F$1) -> "false" | AA14: =IF($A14="Implicit","",$F$1&IF(OR(E14="Enum",E14="CodeList"),"true","false")&$F$1) -> "false" | AB14: =IF($A14="Implicit","",$F$1&P14&$F$1) -> "" | AC14: =IF($A14="Implicit","",$F$1&C14&$F$1) -> "https://onerecord.iata.org/ns/cargo#AccountType" | AD14: =IF($A14="Implicit","",$F$1&D14&$F$1) -> "https://onerecord.iata.org/ns/cargo#codeListName" | AE14: =IF($A14="Implicit","",$F$1&F14&$F$1) -> "http://www.w3.org/2001/XMLSchema#string" | AF14: =IF(A14="Implicit","",R14&","&S14&","&T14&","&U14&","&V14&","&W14&","&X14&","&Y14&","&Z14&","&AA14&","&AB14&","&AC14&","&AD14&","&AE14) -> "Enum","AccountType","codeListName","","string",4,"Open code list for Account types","Official name of the code list without version number when direct reference is not possible; for example "UN/LOCODE" when referring to the UN/LOCODE code list","false","false","","https://onerecord.iata.org/ns/cargo#AccountType","https://onerecord.iata.org/ns/cargo#codeListName","http://www.w3.org/2001/XMLSchema#string" | AG14: =IF(Q14="Data","",$F$1&B14&"."&L14&$F$1) -> "Enum.AccountType" | AH14: =IF(Q14="Data","",$F$1&M14&$F$1) -> "codeListName" | AI14: =IF(Q14="Data","",$F$1&E14&"."&N14&$F$1) -> ".string" | AJ14: =IF(Q14="Data","",$F$1&O14&$F$1) -> "" | AK14: =IF(Q14="Data","",$F$1&IF(G14=1,"hasOne","hasMany")&$F$1) -> "hasOne" | AL14: =IF(Q14="Data","",AG14&","&AH14&","&AI14&","&AJ14&","&AK14) -> "Enum.AccountType","codeListName",".string","","hasOne" | AN14: =COUNTIF(View_conceptual!G:G,L14) -> 0 | AO14: =COUNTIF(View_conceptual!H:H,L14)+COUNTIF(View_conceptual!I:I,N14) -> 0 | AQ14: =IF(AN14=1,AF14,"") | AR14: =IF(AO14=2,AL14,"") | AT14: =COUNTIF(View_full!G:G,L14) -> 0 | AU14: =COUNTIF(View_full!H:H,L14)+COUNTIF(View_full!I:I,N14) -> 0 | AV14: =COUNTIFS(Property_Manual!$A$2:$A$1206,Raw!L14,Property_Manual!$B$2:$B$1206,Raw!M14,Property_Manual!$C$2:$C$1206,Raw!N14,Property_Manual!$D$2:$D$1206,Raw!O14,Property_Manual!$F$2:$F$1206,"x") -> 0 | AW14: =IF(AT14=1,AF14,"") | AX14: =IF(AU14=2,AL14,"") | AY14: =IF(AV14=1,AL14,"")
A15: Explicit | B15: Enum | C15: https://onerecord.iata.org/ns/cargo#AccountType | D15: https://onerecord.iata.org/ns/cargo#codeListReference | F15: http://www.w3.org/2001/XMLSchema#string | G15: 1 | I15: Open code list for Account types | J15: URL to access the code list the code is taken from, for example "https://unece.org/trade/cefact/unlocode-code-list-country-and-territory" for UN/LOCODE. | L15: =SUBSTITUTE(SUBSTITUTE(SUBSTITUTE(C15,$B$2,$A$2),$B$3,$A$3),$B$4,$A$4) -> AccountType | M15: =SUBSTITUTE(SUBSTITUTE(SUBSTITUTE(D15,$B$2,$A$2),$B$3,$A$3),$A$4,$B$4) -> codeListReference | N15: =SUBSTITUTE(SUBSTITUTE(SUBSTITUTE(F15,$B$2,$A$2),$B$3,$A$3),$B$4,$A$4) -> string | O15: =SUBSTITUTE(SUBSTITUTE(SUBSTITUTE(H15,$B$2,$A$2),$B$3,$A$3),$B$4,$A$4) | P15: =SUBSTITUTE(SUBSTITUTE(SUBSTITUTE(K15,$B$2,$A$2),$B$3,$A$3),$B$4,$A$4) | Q15: =IF(LEFT(N15,3)="xsd","Data","Object") -> Object | R15: =IF($A15="Implicit","",$F$1&B15&$F$1) -> "Enum" | S15: =IF($A15="Implicit","",$F$1&L15&$F$1) -> "AccountType" | T15: =IF($A15="Implicit","",$F$1&M15&$F$1) -> "codeListReference" | U15: =IF($A15="Implicit","",$F$1&E15&$F$1) -> "" | V15: =IF($A15="Implicit","",$F$1&N15&$F$1) -> "string" | W15: =IF($A15="Implicit","",COUNTIFS($C$8:C15,C15,$A$8:A15,"Explicit")) -> 5 | X15: =IF($A15="Implicit","",$F$1&SUBSTITUTE(IF(I15=0,"",I15),",",";")&$F$1) -> "Open code list for Account types" | Y15: =IF($A15="Implicit","",$F$1&SUBSTITUTE(IF(J15=0,"",J15),",",";")&$F$1) -> "URL to access the code list the code is taken from; for example "https://unece.org/trade/cefact/unlocode-code-list-country-and-territory" for UN/LOCODE." | Z15: =IF($A15="Implicit","",$F$1&IF(G15=1,"false","true")&$F$1) -> "false" | AA15: =IF($A15="Implicit","",$F$1&IF(OR(E15="Enum",E15="CodeList"),"true","false")&$F$1) -> "false" | AB15: =IF($A15="Implicit","",$F$1&P15&$F$1) -> "" | AC15: =IF($A15="Implicit","",$F$1&C15&$F$1) -> "https://onerecord.iata.org/ns/cargo#AccountType" | AD15: =IF($A15="Implicit","",$F$1&D15&$F$1) -> "https://onerecord.iata.org/ns/cargo#codeListReference" | AE15: =IF($A15="Implicit","",$F$1&F15&$F$1) -> "http://www.w3.org/2001/XMLSchema#string" | AF15: =IF(A15="Implicit","",R15&","&S15&","&T15&","&U15&","&V15&","&W15&","&X15&","&Y15&","&Z15&","&AA15&","&AB15&","&AC15&","&AD15&","&AE15) -> "Enum","AccountType","codeListReference","","string",5,"Open code list for Account types","URL to access the code list the code is taken from; for example "https://unece.org/trade/cefact/unlocode-code-list-country-and-territory" for UN/LOCODE.","false","false","","https://onerecord.iata.org/ns/cargo#AccountType","https://onerecord.iata.org/ns/cargo#codeListReference","http://www.w3.org/2001/XMLSchema#string" | AG15: =IF(Q15="Data","",$F$1&B15&"."&L15&$F$1) -> "Enum.AccountType" | AH15: =IF(Q15="Data","",$F$1&M15&$F$1) -> "codeListReference" | AI15: =IF(Q15="Data","",$F$1&E15&"."&N15&$F$1) -> ".string" | AJ15: =IF(Q15="Data","",$F$1&O15&$F$1) -> "" | AK15: =IF(Q15="Data","",$F$1&IF(G15=1,"hasOne","hasMany")&$F$1) -> "hasOne" | AL15: =IF(Q15="Data","",AG15&","&AH15&","&AI15&","&AJ15&","&AK15) -> "Enum.AccountType","codeListReference",".string","","hasOne" | AN15: =COUNTIF(View_conceptual!G:G,L15) -> 0 | AO15: =COUNTIF(View_conceptual!H:H,L15)+COUNTIF(View_conceptual!I:I,N15) -> 0 | AQ15: =IF(AN15=1,AF15,"") | AR15: =IF(AO15=2,AL15,"") | AT15: =COUNTIF(View_full!G:G,L15) -> 0 | AU15: =COUNTIF(View_full!H:H,L15)+COUNTIF(View_full!I:I,N15) -> 0 | AV15: =COUNTIFS(Property_Manual!$A$2:$A$1206,Raw!L15,Property_Manual!$B$2:$B$1206,Raw!M15,Property_Manual!$C$2:$C$1206,Raw!N15,Property_Manual!$D$2:$D$1206,Raw!O15,Property_Manual!$F$2:$F$1206,"x") -> 0 | AW15: =IF(AT15=1,AF15,"") | AX15: =IF(AU15=2,AL15,"") | AY15: =IF(AV15=1,AL15,"")
A16: Explicit | B16: Enum | C16: https://onerecord.iata.org/ns/cargo#AccountType | D16: https://onerecord.iata.org/ns/cargo#codeListVersion | F16: http://www.w3.org/2001/XMLSchema#string | G16: 1 | I16: Open code list for Account types | J16: Version of the code list, for example "223-1" for UN/LOCODE. Used if the property codeListName is used or the version is not apparent from the resource referred to in property codeListReference. | L16: =SUBSTITUTE(SUBSTITUTE(SUBSTITUTE(C16,$B$2,$A$2),$B$3,$A$3),$B$4,$A$4) -> AccountType | M16: =SUBSTITUTE(SUBSTITUTE(SUBSTITUTE(D16,$B$2,$A$2),$B$3,$A$3),$A$4,$B$4) -> codeListVersion | N16: =SUBSTITUTE(SUBSTITUTE(SUBSTITUTE(F16,$B$2,$A$2),$B$3,$A$3),$B$4,$A$4) -> string | O16: =SUBSTITUTE(SUBSTITUTE(SUBSTITUTE(H16,$B$2,$A$2),$B$3,$A$3),$B$4,$A$4) | P16: =SUBSTITUTE(SUBSTITUTE(SUBSTITUTE(K16,$B$2,$A$2),$B$3,$A$3),$B$4,$A$4) | Q16: =IF(LEFT(N16,3)="xsd","Data","Object") -> Object | R16: =IF($A16="Implicit","",$F$1&B16&$F$1) -> "Enum" | S16: =IF($A16="Implicit","",$F$1&L16&$F$1) -> "AccountType" | T16: =IF($A16="Implicit","",$F$1&M16&$F$1) -> "codeListVersion" | U16: =IF($A16="Implicit","",$F$1&E16&$F$1) -> "" | V16: =IF($A16="Implicit","",$F$1&N16&$F$1) -> "string" | W16: =IF($A16="Implicit","",COUNTIFS($C$8:C16,C16,$A$8:A16,"Explicit")) -> 6 | X16: =IF($A16="Implicit","",$F$1&SUBSTITUTE(IF(I16=0,"",I16),",",";")&$F$1) -> "Open code list for Account types" | Y16: =IF($A16="Implicit","",$F$1&SUBSTITUTE(IF(J16=0,"",J16),",",";")&$F$1) -> "Version of the code list; for example "223-1" for UN/LOCODE. Used if the property codeListName is used or the version is not apparent from the resource referred to in property codeListReference." | Z16: =IF($A16="Implicit","",$F$1&IF(G16=1,"false","true")&$F$1) -> "false" | AA16: =IF($A16="Implicit","",$F$1&IF(OR(E16="Enum",E16="CodeList"),"true","false")&$F$1) -> "false" | AB16: =IF($A16="Implicit","",$F$1&P16&$F$1) -> "" | AC16: =IF($A16="Implicit","",$F$1&C16&$F$1) -> "https://onerecord.iata.org/ns/cargo#AccountType" | AD16: =IF($A16="Implicit","",$F$1&D16&$F$1) -> "https://onerecord.iata.org/ns/cargo#codeListVersion" | AE16: =IF($A16="Implicit","",$F$1&F16&$F$1) -> "http://www.w3.org/2001/XMLSchema#string" | AF16: =IF(A16="Implicit","",R16&","&S16&","&T16&","&U16&","&V16&","&W16&","&X16&","&Y16&","&Z16&","&AA16&","&AB16&","&AC16&","&AD16&","&AE16) -> "Enum","AccountType","codeListVersion","","string",6,"Open code list for Account types","Version of the code list; for example "223-1" for UN/LOCODE. Used if the property codeListName is used or the version is not apparent from the resource referred to in property codeListReference.","false","false","","https://onerecord.iata.org/ns/cargo#AccountType","https://onerecord.iata.org/ns/cargo#codeListVersion","http://www.w3.org/2001/XMLSchema#string" | AG16: =IF(Q16="Data","",$F$1&B16&"."&L16&$F$1) -> "Enum.AccountType" | AH16: =IF(Q16="Data","",$F$1&M16&$F$1) -> "codeListVersion" | AI16: =IF(Q16="Data","",$F$1&E16&"."&N16&$F$1) -> ".string" | AJ16: =IF(Q16="Data","",$F$1&O16&$F$1) -> "" | AK16: =IF(Q16="Data","",$F$1&IF(G16=1,"hasOne","hasMany")&$F$1) -> "hasOne" | AL16: =IF(Q16="Data","",AG16&","&AH16&","&AI16&","&AJ16&","&AK16) -> "Enum.AccountType","codeListVersion",".string","","hasOne" | AN16: =COUNTIF(View_conceptual!G:G,L16) -> 0 | AO16: =COUNTIF(View_conceptual!H:H,L16)+COUNTIF(View_conceptual!I:I,N16) -> 0 | AQ16: =IF(AN16=1,AF16,"") | AR16: =IF(AO16=2,AL16,"") | AT16: =COUNTIF(View_full!G:G,L16) -> 0 | AU16: =COUNTIF(View_full!H:H,L16)+COUNTIF(View_full!I:I,N16) -> 0 | AV16: =COUNTIFS(Property_Manual!$A$2:$A$1206,Raw!L16,Property_Manual!$B$2:$B$1206,Raw!M16,Property_Manual!$C$2:$C$1206,Raw!N16,Property_Manual!$D$2:$D$1206,Raw!O16,Property_Manual!$F$2:$F$1206,"x") -> 0 | AW16: =IF(AT16=1,AF16,"") | AX16: =IF(AU16=2,AL16,"") | AY16: =IF(AV16=1,AL16,"")
A17: Explicit | B17: Embedded | C17: https://onerecord.iata.org/ns/cargo#AccountingNote | D17: https://onerecord.iata.org/ns/cargo#accountingNoteIdentifier | F17: http://www.w3.org/2001/XMLSchema#string | G17: 1 | I17: Embedded object used for AWB mapping (box 10) | J17: String holding accounting information (AWB box 10) | L17: =SUBSTITUTE(SUBSTITUTE(SUBSTITUTE(C17,$B$2,$A$2),$B$3,$A$3),$B$4,$A$4) -> AccountingNote | M17: =SUBSTITUTE(SUBSTITUTE(SUBSTITUTE(D17,$B$2,$A$2),$B$3,$A$3),$A$4,$B$4) -> accountingNoteIdentifier | N17: =SUBSTITUTE(SUBSTITUTE(SUBSTITUTE(F17,$B$2,$A$2),$B$3,$A$3),$B$4,$A$4) -> string | O17: =SUBSTITUTE(SUBSTITUTE(SUBSTITUTE(H17,$B$2,$A$2),$B$3,$A$3),$B$4,$A$4) | P17: =SUBSTITUTE(SUBSTITUTE(SUBSTITUTE(K17,$B$2,$A$2),$B$3,$A$3),$B$4,$A$4) | Q17: =IF(LEFT(N17,3)="xsd","Data","Object") -> Object | R17: =IF($A17="Implicit","",$F$1&B17&$F$1) -> "Embedded" | S17: =IF($A17="Implicit","",$F$1&L17&$F$1) -> "AccountingNote" | T17: =IF($A17="Implicit","",$F$1&M17&$F$1) -> "accountingNoteIdentifier" | U17: =IF($A17="Implicit","",$F$1&E17&$F$1) -> "" | V17: =IF($A17="Implicit","",$F$1&N17&$F$1) -> "string" | W17: =IF($A17="Implicit","",COUNTIFS($C$8:C17,C17,$A$8:A17,"Explicit")) -> 1 | X17: =IF($A17="Implicit","",$F$1&SUBSTITUTE(IF(I17=0,"",I17),",",";")&$F$1) -> "Embedded object used for AWB mapping (box 10)" | Y17: =IF($A17="Implicit","",$F$1&SUBSTITUTE(IF(J17=0,"",J17),",",";")&$F$1) -> "String holding accounting information (AWB box 10)" | Z17: =IF($A17="Implicit","",$F$1&IF(G17=1,"false","true")&$F$1) -> "false" | AA17: =IF($A17="Implicit","",$F$1&IF(OR(E17="Enum",E17="CodeList"),"true","false")&$F$1) -> "false" | AB17: =IF($A17="Implicit","",$F$1&P17&$F$1) -> "" | AC17: =IF($A17="Implicit","",$F$1&C17&$F$1) -> "https://onerecord.iata.org/ns/cargo#AccountingNote" | AD17: =IF($A17="Implicit","",$F$1&D17&$F$1) -> "https://onerecord.iata.org/ns/cargo#accountingNoteIdentifier" | AE17: =IF($A17="Implicit","",$F$1&F17&$F$1) -> "http://www.w3.org/2001/XMLSchema#string" | AF17: =IF(A17="Implicit","",R17&","&S17&","&T17&","&U17&","&V17&","&W17&","&X17&","&Y17&","&Z17&","&AA17&","&AB17&","&AC17&","&AD17&","&AE17) -> "Embedded","AccountingNote","accountingNoteIdentifier","","string",1,"Embedded object used for AWB mapping (box 10)","String holding accounting information (AWB box 10)","false","false","","https://onerecord.iata.org/ns/cargo#AccountingNote","https://onerecord.iata.org/ns/cargo#accountingNoteIdentifier","http://www.w3.org/2001/XMLSchema#string" | AG17: =IF(Q17="Data","",$F$1&B17&"."&L17&$F$1) -> "Embedded.AccountingNote" | AH17: =IF(Q17="Data","",$F$1&M17&$F$1) -> "accountingNoteIdentifier" | AI17: =IF(Q17="Data","",$F$1&E17&"."&N17&$F$1) -> ".string" | AJ17: =IF(Q17="Data","",$F$1&O17&$F$1) -> "" | AK17: =IF(Q17="Data","",$F$1&IF(G17=1,"hasOne","hasMany")&$F$1) -> "hasOne" | AL17: =IF(Q17="Data","",AG17&","&AH17&","&AI17&","&AJ17&","&AK17) -> "Embedded.AccountingNote","accountingNoteIdentifier",".string","","hasOne" | AN17: =COUNTIF(View_conceptual!G:G,L17) -> 0 | AO17: =COUNTIF(View_conceptual!H:H,L17)+COUNTIF(View_conceptual!I:I,N17) -> 0 | AQ17: =IF(AN17=1,AF17,"") | AR17: =IF(AO17=2,AL17,"") | AT17: =COUNTIF(View_full!G:G,L17) -> 1 | AU17: =COUNTIF(View_full!H:H,L17)+COUNTIF(View_full!I:I,N17) -> 1 | AV17: =COUNTIFS(Property_Manual!$A$2:$A$1206,Raw!L17,Property_Manual!$B$2:$B$1206,Raw!M17,Property_Manual!$C$2:$C$1206,Raw!N17,Property_Manual!$D$2:$D$1206,Raw!O17,Property_Manual!$F$2:$F$1206,"x") -> 0 | AW17: =IF(AT17=1,AF17,"") -> "Embedded","AccountingNote","accountingNoteIdentifier","","string",1,"Embedded object used for AWB mapping (box 10)","String holding accounting information (AWB box 10)","false","false","","https://onerecord.iata.org/ns/cargo#AccountingNote","https://onerecord.iata.org/ns/cargo#accountingNoteIdentifier","http://www.w3.org/2001/XMLSchema#string" | AX17: =IF(AU17=2,AL17,"") | AY17: =IF(AV17=1,AL17,"")
A18: Explicit | B18: Embedded | C18: https://onerecord.iata.org/ns/cargo#AccountingNote | D18: https://onerecord.iata.org/ns/cargo#accountingNoteText | F18: http://www.w3.org/2001/XMLSchema#string | G18: 1 | I18: Embedded object used for AWB mapping (box 10) | J18: String holding the identifier in an accounting note (AWB box 10) | L18: =SUBSTITUTE(SUBSTITUTE(SUBSTITUTE(C18,$B$2,$A$2),$B$3,$A$3),$B$4,$A$4) -> AccountingNote | M18: =SUBSTITUTE(SUBSTITUTE(SUBSTITUTE(D18,$B$2,$A$2),$B$3,$A$3),$A$4,$B$4) -> accountingNoteText | N18: =SUBSTITUTE(SUBSTITUTE(SUBSTITUTE(F18,$B$2,$A$2),$B$3,$A$3),$B$4,$A$4) -> string | O18: =SUBSTITUTE(SUBSTITUTE(SUBSTITUTE(H18,$B$2,$A$2),$B$3,$A$3),$B$4,$A$4) | P18: =SUBSTITUTE(SUBSTITUTE(SUBSTITUTE(K18,$B$2,$A$2),$B$3,$A$3),$B$4,$A$4) | Q18: =IF(LEFT(N18,3)="xsd","Data","Object") -> Object | R18: =IF($A18="Implicit","",$F$1&B18&$F$1) -> "Embedded" | S18: =IF($A18="Implicit","",$F$1&L18&$F$1) -> "AccountingNote" | T18: =IF($A18="Implicit","",$F$1&M18&$F$1) -> "accountingNoteText" | U18: =IF($A18="Implicit","",$F$1&E18&$F$1) -> "" | V18: =IF($A18="Implicit","",$F$1&N18&$F$1) -> "string" | W18: =IF($A18="Implicit","",COUNTIFS($C$8:C18,C18,$A$8:A18,"Explicit")) -> 2 | X18: =IF($A18="Implicit","",$F$1&SUBSTITUTE(IF(I18=0,"",I18),",",";")&$F$1) -> "Embedded object used for AWB mapping (box 10)" | Y18: =IF($A18="Implicit","",$F$1&SUBSTITUTE(IF(J18=0,"",J18),",",";")&$F$1) -> "String holding the identifier in an accounting note (AWB box 10)" | Z18: =IF($A18="Implicit","",$F$1&IF(G18=1,"false","true")&$F$1) -> "false" | AA18: =IF($A18="Implicit","",$F$1&IF(OR(E18="Enum",E18="CodeList"),"true","false")&$F$1) -> "false" | AB18: =IF($A18="Implicit","",$F$1&P18&$F$1) -> "" | AC18: =IF($A18="Implicit","",$F$1&C18&$F$1) -> "https://onerecord.iata.org/ns/cargo#AccountingNote" | AD18: =IF($A18="Implicit","",$F$1&D18&$F$1) -> "https://onerecord.iata.org/ns/cargo#accountingNoteText" | AE18: =IF($A18="Implicit","",$F$1&F18&$F$1) -> "http://www.w3.org/2001/XMLSchema#string" | AF18: =IF(A18="Implicit","",R18&","&S18&","&T18&","&U18&","&V18&","&W18&","&X18&","&Y18&","&Z18&","&AA18&","&AB18&","&AC18&","&AD18&","&AE18) -> "Embedded","AccountingNote","accountingNoteText","","string",2,"Embedded object used for AWB mapping (box 10)","String holding the identifier in an accounting note (AWB box 10)","false","false","","https://onerecord.iata.org/ns/cargo#AccountingNote","https://onerecord.iata.org/ns/cargo#accountingNoteText","http://www.w3.org/2001/XMLSchema#string" | AG18: =IF(Q18="Data","",$F$1&B18&"."&L18&$F$1) -> "Embedded.AccountingNote" | AH18: =IF(Q18="Data","",$F$1&M18&$F$1) -> "accountingNoteText" | AI18: =IF(Q18="Data","",$F$1&E18&"."&N18&$F$1) -> ".string" | AJ18: =IF(Q18="Data","",$F$1&O18&$F$1) -> "" | AK18: =IF(Q18="Data","",$F$1&IF(G18=1,"hasOne","hasMany")&$F$1) -> "hasOne" | AL18: =IF(Q18="Data","",AG18&","&AH18&","&AI18&","&AJ18&","&AK18) -> "Embedded.AccountingNote","accountingNoteText",".string","","hasOne" | AN18: =COUNTIF(View_conceptual!G:G,L18) -> 0 | AO18: =COUNTIF(View_conceptual!H:H,L18)+COUNTIF(View_conceptual!I:I,N18) -> 0 | AQ18: =IF(AN18=1,AF18,"") | AR18: =IF(AO18=2,AL18,"") | AT18: =COUNTIF(View_full!G:G,L18) -> 1 | AU18: =COUNTIF(View_full!H:H,L18)+COUNTIF(View_full!I:I,N18) -> 1 | AV18: =COUNTIFS(Property_Manual!$A$2:$A$1206,Raw!L18,Property_Manual!$B$2:$B$1206,Raw!M18,Property_Manual!$C$2:$C$1206,Raw!N18,Property_Manual!$D$2:$D$1206,Raw!O18,Property_Manual!$F$2:$F$1206,"x") -> 0 | AW18: =IF(AT18=1,AF18,"") -> "Embedded","AccountingNote","accountingNoteText","","string",2,"Embedded object used for AWB mapping (box 10)","String holding the identifier in an accounting note (AWB box 10)","false","false","","https://onerecord.iata.org/ns/cargo#AccountingNote","https://onerecord.iata.org/ns/cargo#accountingNoteText","http://www.w3.org/2001/XMLSchema#string" | AX18: =IF(AU18=2,AL18,"") | AY18: =IF(AV18=1,AL18,"")
A19: Explicit | B19: Enum | C19: https://onerecord.iata.org/ns/cargo#ActionTimeType | D19: https://onerecord.iata.org/ns/cargo#code | F19: http://www.w3.org/2001/XMLSchema#string | G19: 1 | I19: Restricted code list for acceptable action times | J19: Code or short version of a code, for example "CH" for Switzerland when referring to the UN/LOCODE code list | L19: =SUBSTITUTE(SUBSTITUTE(SUBSTITUTE(C19,$B$2,$A$2),$B$3,$A$3),$B$4,$A$4) -> ActionTimeType | M19: =SUBSTITUTE(SUBSTITUTE(SUBSTITUTE(D19,$B$2,$A$2),$B$3,$A$3),$A$4,$B$4) -> code | N19: =SUBSTITUTE(SUBSTITUTE(SUBSTITUTE(F19,$B$2,$A$2),$B$3,$A$3),$B$4,$A$4) -> string | O19: =SUBSTITUTE(SUBSTITUTE(SUBSTITUTE(H19,$B$2,$A$2),$B$3,$A$3),$B$4,$A$4) | P19: =SUBSTITUTE(SUBSTITUTE(SUBSTITUTE(K19,$B$2,$A$2),$B$3,$A$3),$B$4,$A$4) | Q19: =IF(LEFT(N19,3)="xsd","Data","Object") -> Object | R19: =IF($A19="Implicit","",$F$1&B19&$F$1) -> "Enum" | S19: =IF($A19="Implicit","",$F$1&L19&$F$1) -> "ActionTimeType" | T19: =IF($A19="Implicit","",$F$1&M19&$F$1) -> "code" | U19: =IF($A19="Implicit","",$F$1&E19&$F$1) -> "" | V19: =IF($A19="Implicit","",$F$1&N19&$F$1) -> "string" | W19: =IF($A19="Implicit","",COUNTIFS($C$8:C19,C19,$A$8:A19,"Explicit")) -> 1 | X19: =IF($A19="Implicit","",$F$1&SUBSTITUTE(IF(I19=0,"",I19),",",";")&$F$1) -> "Restricted code list for acceptable action times" | Y19: =IF($A19="Implicit","",$F$1&SUBSTITUTE(IF(J19=0,"",J19),",",";")&$F$1) -> "Code or short version of a code; for example "CH" for Switzerland when referring to the UN/LOCODE code list" | Z19: =IF($A19="Implicit","",$F$1&IF(G19=1,"false","true")&$F$1) -> "false" | AA19: =IF($A19="Implicit","",$F$1&IF(OR(E19="Enum",E19="CodeList"),"true","false")&$F$1) -> "false" | AB19: =IF($A19="Implicit","",$F$1&P19&$F$1) -> "" | AC19: =IF($A19="Implicit","",$F$1&C19&$F$1) -> "https://onerecord.iata.org/ns/cargo#ActionTimeType" | AD19: =IF($A19="Implicit","",$F$1&D19&$F$1) -> "https://onerecord.iata.org/ns/cargo#code" | AE19: =IF($A19="Implicit","",$F$1&F19&$F$1) -> "http://www.w3.org/2001/XMLSchema#string" | AF19: =IF(A19="Implicit","",R19&","&S19&","&T19&","&U19&","&V19&","&W19&","&X19&","&Y19&","&Z19&","&AA19&","&AB19&","&AC19&","&AD19&","&AE19) -> "Enum","ActionTimeType","code","","string",1,"Restricted code list for acceptable action times","Code or short version of a code; for example "CH" for Switzerland when referring to the UN/LOCODE code list","false","false","","https://onerecord.iata.org/ns/cargo#ActionTimeType","https://onerecord.iata.org/ns/cargo#code","http://www.w3.org/2001/XMLSchema#string" | AG19: =IF(Q19="Data","",$F$1&B19&"."&L19&$F$1) -> "Enum.ActionTimeType" | AH19: =IF(Q19="Data","",$F$1&M19&$F$1) -> "code" | AI19: =IF(Q19="Data","",$F$1&E19&"."&N19&$F$1) -> ".string" | AJ19: =IF(Q19="Data","",$F$1&O19&$F$1) -> "" | AK19: =IF(Q19="Data","",$F$1&IF(G19=1,"hasOne","hasMany")&$F$1) -> "hasOne" | AL19: =IF(Q19="Data","",AG19&","&AH19&","&AI19&","&AJ19&","&AK19) -> "Enum.ActionTimeType","code",".string","","hasOne" | AN19: =COUNTIF(View_conceptual!G:G,L19) -> 0 | AO19: =COUNTIF(View_conceptual!H:H,L19)+COUNTIF(View_conceptual!I:I,N19) -> 0 | AQ19: =IF(AN19=1,AF19,"") | AR19: =IF(AO19=2,AL19,"") | AT19: =COUNTIF(View_full!G:G,L19) -> 0 | AU19: =COUNTIF(View_full!H:H,L19)+COUNTIF(View_full!I:I,N19) -> 0 | AV19: =COUNTIFS(Property_Manual!$A$2:$A$1206,Raw!L19,Property_Manual!$B$2:$B$1206,Raw!M19,Property_Manual!$C$2:$C$1206,Raw!N19,Property_Manual!$D$2:$D$1206,Raw!O19,Property_Manual!$F$2:$F$1206,"x") -> 0 | AW19: =IF(AT19=1,AF19,"") | AX19: =IF(AU19=2,AL19,"") | AY19: =IF(AV19=1,AL19,"")
A20: Explicit | B20: Enum | C20: https://onerecord.iata.org/ns/cargo#ActionTimeType | D20: https://onerecord.iata.org/ns/cargo#codeDescription | F20: http://www.w3.org/2001/XMLSchema#string | G20: 1 | I20: Restricted code list for acceptable action times | J20: Description or long version of the code, for example "Switzerland" for Switzerland when referring to the UN/LOCODE code list | L20: =SUBSTITUTE(SUBSTITUTE(SUBSTITUTE(C20,$B$2,$A$2),$B$3,$A$3),$B$4,$A$4) -> ActionTimeType | M20: =SUBSTITUTE(SUBSTITUTE(SUBSTITUTE(D20,$B$2,$A$2),$B$3,$A$3),$A$4,$B$4) -> codeDescription | N20: =SUBSTITUTE(SUBSTITUTE(SUBSTITUTE(F20,$B$2,$A$2),$B$3,$A$3),$B$4,$A$4) -> string | O20: =SUBSTITUTE(SUBSTITUTE(SUBSTITUTE(H20,$B$2,$A$2),$B$3,$A$3),$B$4,$A$4) | P20: =SUBSTITUTE(SUBSTITUTE(SUBSTITUTE(K20,$B$2,$A$2),$B$3,$A$3),$B$4,$A$4) | Q20: =IF(LEFT(N20,3)="xsd","Data","Object") -> Object | R20: =IF($A20="Implicit","",$F$1&B20&$F$1) -> "Enum" | S20: =IF($A20="Implicit","",$F$1&L20&$F$1) -> "ActionTimeType" | T20: =IF($A20="Implicit","",$F$1&M20&$F$1) -> "codeDescription" | U20: =IF($A20="Implicit","",$F$1&E20&$F$1) -> "" | V20: =IF($A20="Implicit","",$F$1&N20&$F$1) -> "string" | W20: =IF($A20="Implicit","",COUNTIFS($C$8:C20,C20,$A$8:A20,"Explicit")) -> 2 | X20: =IF($A20="Implicit","",$F$1&SUBSTITUTE(IF(I20=0,"",I20),",",";")&$F$1) -> "Restricted code list for acceptable action times" | Y20: =IF($A20="Implicit","",$F$1&SUBSTITUTE(IF(J20=0,"",J20),",",";")&$F$1) -> "Description or long version of the code; for example "Switzerland" for Switzerland when referring to the UN/LOCODE code list" | Z20: =IF($A20="Implicit","",$F$1&IF(G20=1,"false","true")&$F$1) -> "false" | AA20: =IF($A20="Implicit","",$F$1&IF(OR(E20="Enum",E20="CodeList"),"true","false")&$F$1) -> "false" | AB20: =IF($A20="Implicit","",$F$1&P20&$F$1) -> "" | AC20: =IF($A20="Implicit","",$F$1&C20&$F$1) -> "https://onerecord.iata.org/ns/cargo#ActionTimeType" | AD20: =IF($A20="Implicit","",$F$1&D20&$F$1) -> "https://onerecord.iata.org/ns/cargo#codeDescription" | AE20: =IF($A20="Implicit","",$F$1&F20&$F$1) -> "http://www.w3.org/2001/XMLSchema#string" | AF20: =IF(A20="Implicit","",R20&","&S20&","&T20&","&U20&","&V20&","&W20&","&X20&","&Y20&","&Z20&","&AA20&","&AB20&","&AC20&","&AD20&","&AE20) -> "Enum","ActionTimeType","codeDescription","","string",2,"Restricted code list for acceptable action times","Description or long version of the code; for example "Switzerland" for Switzerland when referring to the UN/LOCODE code list","false","false","","https://onerecord.iata.org/ns/cargo#ActionTimeType","https://onerecord.iata.org/ns/cargo#codeDescription","http://www.w3.org/2001/XMLSchema#string" | AG20: =IF(Q20="Data","",$F$1&B20&"."&L20&$F$1) -> "Enum.ActionTimeType" | AH20: =IF(Q20="Data","",$F$1&M20&$F$1) -> "codeDescription" | AI20: =IF(Q20="Data","",$F$1&E20&"."&N20&$F$1) -> ".string" | AJ20: =IF(Q20="Data","",$F$1&O20&$F$1) -> "" | AK20: =IF(Q20="Data","",$F$1&IF(G20=1,"hasOne","hasMany")&$F$1) -> "hasOne" | AL20: =IF(Q20="Data","",AG20&","&AH20&","&AI20&","&AJ20&","&AK20) -> "Enum.ActionTimeType","codeDescription",".string","","hasOne" | AN20: =COUNTIF(View_conceptual!G:G,L20) -> 0 | AO20: =COUNTIF(View_conceptual!H:H,L20)+COUNTIF(View_conceptual!I:I,N20) -> 0 | AQ20: =IF(AN20=1,AF20,"") | AR20: =IF(AO20=2,AL20,"") | AT20: =COUNTIF(View_full!G:G,L20) -> 0 | AU20: =COUNTIF(View_full!H:H,L20)+COUNTIF(View_full!I:I,N20) -> 0 | AV20: =COUNTIFS(Property_Manual!$A$2:$A$1206,Raw!L20,Property_Manual!$B$2:$B$1206,Raw!M20,Property_Manual!$C$2:$C$1206,Raw!N20,Property_Manual!$D$2:$D$1206,Raw!O20,Property_Manual!$F$2:$F$1206,"x") -> 0 | AW20: =IF(AT20=1,AF20,"") | AX20: =IF(AU20=2,AL20,"") | AY20: =IF(AV20=1,AL20,"")
A21: Explicit | B21: Enum | C21: https://onerecord.iata.org/ns/cargo#ActionTimeType | D21: https://onerecord.iata.org/ns/cargo#codeLevel | F21: http://www.w3.org/2001/XMLSchema#integer | G21: 1 | I21: Restricted code list for acceptable action times | J21: Integer indicating the level of a code if a codelists is hierarchical, for example HS-Codes | L21: =SUBSTITUTE(SUBSTITUTE(SUBSTITUTE(C21,$B$2,$A$2),$B$3,$A$3),$B$4,$A$4) -> ActionTimeType | M21: =SUBSTITUTE(SUBSTITUTE(SUBSTITUTE(D21,$B$2,$A$2),$B$3,$A$3),$A$4,$B$4) -> codeLevel | N21: =SUBSTITUTE(SUBSTITUTE(SUBSTITUTE(F21,$B$2,$A$2),$B$3,$A$3),$B$4,$A$4) -> integer | O21: =SUBSTITUTE(SUBSTITUTE(SUBSTITUTE(H21,$B$2,$A$2),$B$3,$A$3),$B$4,$A$4) | P21: =SUBSTITUTE(SUBSTITUTE(SUBSTITUTE(K21,$B$2,$A$2),$B$3,$A$3),$B$4,$A$4) | Q21: =IF(LEFT(N21,3)="xsd","Data","Object") -> Object | R21: =IF($A21="Implicit","",$F$1&B21&$F$1) -> "Enum" | S21: =IF($A21="Implicit","",$F$1&L21&$F$1) -> "ActionTimeType" | T21: =IF($A21="Implicit","",$F$1&M21&$F$1) -> "codeLevel" | U21: =IF($A21="Implicit","",$F$1&E21&$F$1) -> "" | V21: =IF($A21="Implicit","",$F$1&N21&$F$1) -> "integer" | W21: =IF($A21="Implicit","",COUNTIFS($C$8:C21,C21,$A$8:A21,"Explicit")) -> 3 | X21: =IF($A21="Implicit","",$F$1&SUBSTITUTE(IF(I21=0,"",I21),",",";")&$F$1) -> "Restricted code list for acceptable action times" | Y21: =IF($A21="Implicit","",$F$1&SUBSTITUTE(IF(J21=0,"",J21),",",";")&$F$1) -> "Integer indicating the level of a code if a codelists is hierarchical; for example HS-Codes" | Z21: =IF($A21="Implicit","",$F$1&IF(G21=1,"false","true")&$F$1) -> "false" | AA21: =IF($A21="Implicit","",$F$1&IF(OR(E21="Enum",E21="CodeList"),"true","false")&$F$1) -> "false" | AB21: =IF($A21="Implicit","",$F$1&P21&$F$1) -> "" | AC21: =IF($A21="Implicit","",$F$1&C21&$F$1) -> "https://onerecord.iata.org/ns/cargo#ActionTimeType" | AD21: =IF($A21="Implicit","",$F$1&D21&$F$1) -> "https://onerecord.iata.org/ns/cargo#codeLevel" | AE21: =IF($A21="Implicit","",$F$1&F21&$F$1) -> "http://www.w3.org/2001/XMLSchema#integer" | AF21: =IF(A21="Implicit","",R21&","&S21&","&T21&","&U21&","&V21&","&W21&","&X21&","&Y21&","&Z21&","&AA21&","&AB21&","&AC21&","&AD21&","&AE21) -> "Enum","ActionTimeType","codeLevel","","integer",3,"Restricted code list for acceptable action times","Integer indicating the level of a code if a codelists is hierarchical; for example HS-Codes","false","false","","https://onerecord.iata.org/ns/cargo#ActionTimeType","https://onerecord.iata.org/ns/cargo#codeLevel","http://www.w3.org/2001/XMLSchema#integer" | AG21: =IF(Q21="Data","",$F$1&B21&"."&L21&$F$1) -> "Enum.ActionTimeType" | AH21: =IF(Q21="Data","",$F$1&M21&$F$1) -> "codeLevel" | AI21: =IF(Q21="Data","",$F$1&E21&"."&N21&$F$1) -> ".integer" | AJ21: =IF(Q21="Data","",$F$1&O21&$F$1) -> "" | AK21: =IF(Q21="Data","",$F$1&IF(G21=1,"hasOne","hasMany")&$F$1) -> "hasOne" | AL21: =IF(Q21="Data","",AG21&","&AH21&","&AI21&","&AJ21&","&AK21) -> "Enum.ActionTimeType","codeLevel",".integer","","hasOne" | AN21: =COUNTIF(View_conceptual!G:G,L21) -> 0 | AO21: =COUNTIF(View_conceptual!H:H,L21)+COUNTIF(View_conceptual!I:I,N21) -> 0 | AQ21: =IF(AN21=1,AF21,"") | AR21: =IF(AO21=2,AL21,"") | AT21: =COUNTIF(View_full!G:G,L21) -> 0 | AU21: =COUNTIF(View_full!H:H,L21)+COUNTIF(View_full!I:I,N21) -> 0 | AV21: =COUNTIFS(Property_Manual!$A$2:$A$1206,Raw!L21,Property_Manual!$B$2:$B$1206,Raw!M21,Property_Manual!$C$2:$C$1206,Raw!N21,Property_Manual!$D$2:$D$1206,Raw!O21,Property_Manual!$F$2:$F$1206,"x") -> 0 | AW21: =IF(AT21=1,AF21,"") | AX21: =IF(AU21=2,AL21,"") | AY21: =IF(AV21=1,AL21,"")
A22: Explicit | B22: Enum | C22: https://onerecord.iata.org/ns/cargo#ActionTimeType | D22: https://onerecord.iata.org/ns/cargo#codeListName | F22: http://www.w3.org/2001/XMLSchema#string | G22: 1 | I22: Restricted code list for acceptable action times | J22: Official name of the code list without version number when direct reference is not possible, for example "UN/LOCODE" when referring to the UN/LOCODE code list | L22: =SUBSTITUTE(SUBSTITUTE(SUBSTITUTE(C22,$B$2,$A$2),$B$3,$A$3),$B$4,$A$4) -> ActionTimeType | M22: =SUBSTITUTE(SUBSTITUTE(SUBSTITUTE(D22,$B$2,$A$2),$B$3,$A$3),$A$4,$B$4) -> codeListName | N22: =SUBSTITUTE(SUBSTITUTE(SUBSTITUTE(F22,$B$2,$A$2),$B$3,$A$3),$B$4,$A$4) -> string | O22: =SUBSTITUTE(SUBSTITUTE(SUBSTITUTE(H22,$B$2,$A$2),$B$3,$A$3),$B$4,$A$4) | P22: =SUBSTITUTE(SUBSTITUTE(SUBSTITUTE(K22,$B$2,$A$2),$B$3,$A$3),$B$4,$A$4) | Q22: =IF(LEFT(N22,3)="xsd","Data","Object") -> Object | R22: =IF($A22="Implicit","",$F$1&B22&$F$1) -> "Enum" | S22: =IF($A22="Implicit","",$F$1&L22&$F$1) -> "ActionTimeType" | T22: =IF($A22="Implicit","",$F$1&M22&$F$1) -> "codeListName" | U22: =IF($A22="Implicit","",$F$1&E22&$F$1) -> "" | V22: =IF($A22="Implicit","",$F$1&N22&$F$1) -> "string" | W22: =IF($A22="Implicit","",COUNTIFS($C$8:C22,C22,$A$8:A22,"Explicit")) -> 4 | X22: =IF($A22="Implicit","",$F$1&SUBSTITUTE(IF(I22=0,"",I22),",",";")&$F$1) -> "Restricted code list for acceptable action times" | Y22: =IF($A22="Implicit","",$F$1&SUBSTITUTE(IF(J22=0,"",J22),",",";")&$F$1) -> "Official name of the code list without version number when direct reference is not possible; for example "UN/LOCODE" when referring to the UN/LOCODE code list" | Z22: =IF($A22="Implicit","",$F$1&IF(G22=1,"false","true")&$F$1) -> "false" | AA22: =IF($A22="Implicit","",$F$1&IF(OR(E22="Enum",E22="CodeList"),"true","false")&$F$1) -> "false" | AB22: =IF($A22="Implicit","",$F$1&P22&$F$1) -> "" | AC22: =IF($A22="Implicit","",$F$1&C22&$F$1) -> "https://onerecord.iata.org/ns/cargo#ActionTimeType" | AD22: =IF($A22="Implicit","",$F$1&D22&$F$1) -> "https://onerecord.iata.org/ns/cargo#codeListName" | AE22: =IF($A22="Implicit","",$F$1&F22&$F$1) -> "http://www.w3.org/2001/XMLSchema#string" | AF22: =IF(A22="Implicit","",R22&","&S22&","&T22&","&U22&","&V22&","&W22&","&X22&","&Y22&","&Z22&","&AA22&","&AB22&","&AC22&","&AD22&","&AE22) -> "Enum","ActionTimeType","codeListName","","string",4,"Restricted code list for acceptable action times","Official name of the code list without version number when direct reference is not possible; for example "UN/LOCODE" when referring to the UN/LOCODE code list","false","false","","https://onerecord.iata.org/ns/cargo#ActionTimeType","https://onerecord.iata.org/ns/cargo#codeListName","http://www.w3.org/2001/XMLSchema#string" | AG22: =IF(Q22="Data","",$F$1&B22&"."&L22&$F$1) -> "Enum.ActionTimeType" | AH22: =IF(Q22="Data","",$F$1&M22&$F$1) -> "codeListName" | AI22: =IF(Q22="Data","",$F$1&E22&"."&N22&$F$1) -> ".string" | AJ22: =IF(Q22="Data","",$F$1&O22&$F$1) -> "" | AK22: =IF(Q22="Data","",$F$1&IF(G22=1,"hasOne","hasMany")&$F$1) -> "hasOne" | AL22: =IF(Q22="Data","",AG22&","&AH22&","&AI22&","&AJ22&","&AK22) -> "Enum.ActionTimeType","codeListName",".string","","hasOne" | AN22: =COUNTIF(View_conceptual!G:G,L22) -> 0 | AO22: =COUNTIF(View_conceptual!H:H,L22)+COUNTIF(View_conceptual!I:I,N22) -> 0 | AQ22: =IF(AN22=1,AF22,"") | AR22: =IF(AO22=2,AL22,"") | AT22: =COUNTIF(View_full!G:G,L22) -> 0 | AU22: =COUNTIF(View_full!H:H,L22)+COUNTIF(View_full!I:I,N22) -> 0 | AV22: =COUNTIFS(Property_Manual!$A$2:$A$1206,Raw!L22,Property_Manual!$B$2:$B$1206,Raw!M22,Property_Manual!$C$2:$C$1206,Raw!N22,Property_Manual!$D$2:$D$1206,Raw!O22,Property_Manual!$F$2:$F$1206,"x") -> 0 | AW22: =IF(AT22=1,AF22,"") | AX22: =IF(AU22=2,AL22,"") | AY22: =IF(AV22=1,AL22,"")
... A24: Explicit | B24: Enum | C24: https://onerecord.iata.org/ns/cargo#ActionTimeType | D24: https://onerecord.iata.org/ns/cargo#codeListVersion | F24: http://www.w3.org/2001/XMLSchema#string | G24: 1 | I24: Restricted code list for acceptable action times | J24: Version of the code list, for example "223-1" for UN/LOCODE. Used if the property codeListName is used or the version is not apparent from the resource referred to in property codeListReference. | L24: =SUBSTITUTE(SUBSTITUTE(SUBSTITUTE(C24,$B$2,$A$2),$B$3,$A$3),$B$4,$A$4) -> ActionTimeType | M24: =SUBSTITUTE(SUBSTITUTE(SUBSTITUTE(D24,$B$2,$A$2),$B$3,$A$3),$A$4,$B$4) -> codeListVersion | N24: =SUBSTITUTE(SUBSTITUTE(SUBSTITUTE(F24,$B$2,$A$2),$B$3,$A$3),$B$4,$A$4) -> string | O24: =SUBSTITUTE(SUBSTITUTE(SUBSTITUTE(H24,$B$2,$A$2),$B$3,$A$3),$B$4,$A$4) | P24: =SUBSTITUTE(SUBSTITUTE(SUBSTITUTE(K24,$B$2,$A$2),$B$3,$A$3),$B$4,$A$4) | Q24: =IF(LEFT(N24,3)="xsd","Data","Object") -> Object | R24: =IF($A24="Implicit","",$F$1&B24&$F$1) -> "Enum" | S24: =IF($A24="Implicit","",$F$1&L24&$F$1) -> "ActionTimeType" | T24: =IF($A24="Implicit","",$F$1&M24&$F$1) -> "codeListVersion" | U24: =IF($A24="Implicit","",$F$1&E24&$F$1) -> "" | V24: =IF($A24="Implicit","",$F$1&N24&$F$1) -> "string" | W24: =IF($A24="Implicit","",COUNTIFS($C$8:C24,C24,$A$8:A24,"Explicit")) -> 6 | X24: =IF($A24="Implicit","",$F$1&SUBSTITUTE(IF(I24=0,"",I24),",",";")&$F$1) -> "Restricted code list for acceptable action times" | Y24: =IF($A24="Implicit","",$F$1&SUBSTITUTE(IF(J24=0,"",J24),",",";")&$F$1) -> "Version of the code list; for example "223-1" for UN/LOCODE. Used if the property codeListName is used or the version is not apparent from the resource referred to in property codeListReference." | Z24: =IF($A24="Implicit","",$F$1&IF(G24=1,"false","true")&$F$1) -> "false" | AA24: =IF($A24="Implicit","",$F$1&IF(OR(E24="Enum",E24="CodeList"),"true","false")&$F$1) -> "false" | AB24: =IF($A24="Implicit","",$F$1&P24&$F$1) -> "" | AC24: =IF($A24="Implicit","",$F$1&C24&$F$1) -> "https://onerecord.iata.org/ns/cargo#ActionTimeType" | AD24: =IF($A24="Implicit","",$F$1&D24&$F$1) -> "https://onerecord.iata.org/ns/cargo#codeListVersion" | AE24: =IF($A24="Implicit","",$F$1&F24&$F$1) -> "http://www.w3.org/2001/XMLSchema#string" | AF24: =IF(A24="Implicit","",R24&","&S24&","&T24&","&U24&","&V24&","&W24&","&X24&","&Y24&","&Z24&","&AA24&","&AB24&","&AC24&","&AD24&","&AE24) -> "Enum","ActionTimeType","codeListVersion","","string",6,"Restricted code list for acceptable action times","Version of the code list; for example "223-1" for UN/LOCODE. Used if the property codeListName is used or the version is not apparent from the resource referred to in property codeListReference.","false","false","","https://onerecord.iata.org/ns/cargo#ActionTimeType","https://onerecord.iata.org/ns/cargo#codeListVersion","http://www.w3.org/2001/XMLSchema#string" | AG24: =IF(Q24="Data","",$F$1&B24&"."&L24&$F$1) -> "Enum.ActionTimeType" | AH24: =IF(Q24="Data","",$F$1&M24&$F$1) -> "codeListVersion" | AI24: =IF(Q24="Data","",$F$1&E24&"."&N24&$F$1) -> ".string" | AJ24: =IF(Q24="Data","",$F$1&O24&$F$1) -> "" | AK24: =IF(Q24="Data","",$F$1&IF(G24=1,"hasOne","hasMany")&$F$1) -> "hasOne" | AL24: =IF(Q24="Data","",AG24&","&AH24&","&AI24&","&AJ24&","&AK24) -> "Enum.ActionTimeType","codeListVersion",".string","","hasOne" | AN24: =COUNTIF(View_conceptual!G:G,L24) -> 0 | AO24: =COUNTIF(View_conceptual!H:H,L24)+COUNTIF(View_conceptual!I:I,N24) -> 0 | AQ24: =IF(AN24=1,AF24,"") | AR24: =IF(AO24=2,AL24,"") | AT24: =COUNTIF(View_full!G:G,L24) -> 0 | AU24: =COUNTIF(View_full!H:H,L24)+COUNTIF(View_full!I:I,N24) -> 0 | AV24: =COUNTIFS(Property_Manual!$A$2:$A$1206,Raw!L24,Property_Manual!$B$2:$B$1206,Raw!M24,Property_Manual!$C$2:$C$1206,Raw!N24,Property_Manual!$D$2:$D$1206,Raw!O24,Property_Manual!$F$2:$F$1206,"x") -> 0 | AW24: =IF(AT24=1,AF24,"") | AX24: =IF(AU24=2,AL24,"") | AY24: =IF(AV24=1,AL24,"")
